Workbook

Sheet IMPAYES 2020-2021-2022 (2)

Sheet IMPAYES 2020-2021-2022
B1: TOTAL IMPAYES
A2: AU 02/05/2025 | B2: 20242068
A3: AU 15/05/2025 | B3: 21495470
A4: AU 22/05/2025 | B4: 20300656
A5: AU 29/05/2025 | B5: 20730391
A6: AU 12/06/2025 | B6: 20741808
A7: AU 19/06/2025 | B7: 21232065
A8: AU 04/07/2025 | B8: 21572566
A9: AU 10/07/2025 | B9: 22159613
A10: AU 18/07/2025 | B10: 23082633
A11: AU 25/07/2025 | B11: 22597856
A12: AU 11/08/2025 | B12: 22835782
A13: AU 22/08/2025 | B13: 22074371
... A49: AU 31/07/2026 | B49: 26163575
B51: IMPAYES NABIL | C51: IMPAYES OMAR | D51: IMPAYES DIRECTION | E51: IMPAYES FAYCAL | H51: IMPAYES NAOUFAL | K51: IMPAYES FAHD | N51: IMPAYES GII | P51: IMPAYES LAHCEN | Q51: IMPAYES RACHID | R51: IMPAYES OUSSAMA
A52: AU 02/05/2025 | B52: 11167822 | C52: 2790514.8 | D52: 59708 | E52: 1093381.3 | H52: 579371.56 | K52: 830394.9 | N52: 2080615.7 | P52: 114695.33 | Q52: 1487817.5 | R52: 37746.58
A53: AU 15/05/2025 | B53: 12089610 | C53: 2902202.6 | D53: 59708 | E53: 1551831.3 | H53: 579371.59 | K53: 681793.15 | N53: 1981835.7 | P53: 19300 | Q53: 1617817.5 | R53: 12000
A54: AU 22/05/2025 | B54: 11006951 | C54: 2774642.6 | D54: 59708 | E54: 1584874.3 | H54: 607371.56 | K54: 795123.15 | N54: 1981835.7 | P54: 0 | Q54: 1490150 | R54: 0
A55: AU 29/05/2025 | B55: 10947364 | C55: 2825142.6 | D55: 59708 | E55: 1708526.3 | H55: 664371.56 | K55: 1071082.1 | N55: 2002546.6 | P55: 8500 | Q55: 1443150 | R55: 0
A56: AU 12/06/2025 | B56: 11351491 | C56: 2916922.9 | D56: 59708 | E56: 1068803.2 | H56: 664371.56 | K56: 1127959.2 | N56: 2015999.4 | P56: 63000 | Q56: 1473552.7 | R56: 0
A57: AU 19/06/2025 | B57: 11339356 | C57: 2956234.5 | D57: 59708 | E57: 1015233.7 | H57: 785838.4 | K57: 1367241.7 | N57: 2085999.4 | P57: 128900 | Q57: 1493552.7 | R57: 0
A58: AU 04/07/2025 | B58: 11660099 | C58: 2830647.2 | D58: 59708 | E58: 1005475.7 | H58: 1186871.4 | K58: 1079109.4 | N58: 2098412.4 | P58: 138780 | Q58: 1513462.7 | R58: 0
A59: AU 10/07/2025 | B59: 12098509 | C59: 2674766.4 | D59: 59708 | E59: 1222973.7 | H59: 1264449.5 | K59: 1032860.1 | N59: 2176530.4 | P59: 197753 | Q59: 1407062.7 | R59: 25000
A60: AU 18/07/25 | B60: 12550688 | C60: 2924819.2 | D60: 59708 | E60: 1134669.4 | H60: 1278449.5 | K60: 1165527.2 | N60: 2170520.4 | P60: 352988.52 | Q60: 1420262.7 | R60: 25000
A61: AU 25/07/2025 | B61: 12279855 | C61: 2611982.9 | D61: 59708 | E61: 1172073.2 | H61: 1249949.5 | K61: 1323987.8 | N61: 2036008.1 | P61: 437988.52 | Q61: 1401302.7 | R61: 25000
A62: AU 11/08/2025 | B62: 11964134 | C62: 2911848.4 | D62: 59708 | E62: 976554.8 | H62: 1589945.6 | K62: 1492163.1 | N62: 2043733.1 | P62: 520602.79 | Q62: 1254392.7 | R62: 22700
A63: AU 22/08/2025 | B63: 11617240 | C63: 2832606.4 | D63: 59708 | E63: 939150.95 | H63: 1350087.5 | K63: 1368715.3 | N63: 2059309.2 | P63: 520602.79 | Q63: 1304250.7 | R63: 22700
... A99: AU 31/07/2026 | B99: 11219652 | C99: 3524107.1 | D99: 59708 | E99: 1311978.9 | H99: 4261045.5 | K99: 2135391 | N99: 1972303.3 | P99: 158237.3 | Q99: 1508678.1 | R99: 12474

Sheet Feuil4

Sheet Feuil3

Sheet Feuil2

Sheet Total Impayés
D2: TOTAL DES IMPAYES AU 31/07/2026 | I2: IMPAYES AU 24/07/2026 | K2: VARIATION
B4: TOTAL DES IMPAYES NABIL | G4: =NABIL!H265 -> 11219652 | I4: =NABIL!H269 -> 11591970 | K4: =+($G4-I4)/I4 -> -0.032118616
B6: TOTAL IMPAYES OMAR | G6: =OMAR!H64 -> 3524107.1 | I6: =OMAR!H66 -> 3275457.5 | K6: =+(G6-I6)/I6 -> 0.075912938
B8: TOTAL IMPAYES DIRECTION | G8: =DIRECTION!H10 -> 59708 | I8: =DIRECTION!H13 -> 59708 | K8: =+(G8-I8)/I8 -> 0
B10: TOTAL IMPAYES FAYCAL | G10: =FAYCAL!H42 -> 1311978.9 | I10: =FAYCAL!H45 -> 1239906.9 | K10: =+(G10-I10)/I10 -> 0.058126946
B12: TOTAL IMPAYES NAOUFAL | G12: =NAOUFAL!I97 -> 4261045.5 | I12: =NAOUFAL!I100 -> 4245858.5 | K12: =+(G12-I12)/I12 -> 0.0035768973
B14: TOTAL IMPAYES FAHD | G14: =FAHD!I64 -> 2135391 | I14: =FAHD!I66 -> 2160076 | K14: =+(G14-I14)/I14 -> -0.011427839
B16: TOTAL IMPAYES GII | G16: =GII!H79 -> 1972303.3 | I16: =GII!H82 -> 2020799.1 | K16: =+(G16-I16)/I16 -> -0.023998304
B18: TOTAL IMPAYES LAHCEN | G18: =LAHCEN!I16 -> 158237.3 | I18: =LAHCEN!I19 -> 158237.3 | K18: =+(G18-I18)/I18 -> 0
B20: TOTAL IMPAYES RACHID | G20: =RACHID!I54 -> 1508678.1 | I20: =RACHID!I57 -> 1479362.4 | K20: =+(G20-I20)/I20 -> 0.019816476
B22: TOTAL IMPAYES OUSSAMA | G22: =OUSSAMA!I12 -> 12474 | I22: =+OUSSAMA!I15 -> 12474 | K22: =+(G22-I22)/I22 -> 0
B24: TOTAL GENERAL AU 31/07/2026 | G24: =SUM(G4:G23) -> 26163575
B26: TOTAL GENERAL IMPAYES AU 24/07/2026 | F26: 26243850 | G26: =+($G$24-F26)/F26 -> -0.0030587902
B27: TOTAL GENERAL IMPAYES AU 17/07/2026 | F27: 27355716 | G27: =+($G$24-F27)/F27 -> -0.043579218
B28: TOTAL GENERAL IMPAYES AU 10/07/2025 | F28: 27899115 | G28: =+($G$24-F28)/F28 -> -0.062207709

Sheet NABIL
B3: LISTE DES IMPAYES NABIL AU 31/07/2026
A5: NOM CLIENT | B5: COM | C5: Dte Facture | D5: M | E5: Bqe | F5: N° | G5: Échéance | H5: Montant | I5: Commentaire
A6: DHIBA CONSTRUCTION | B6: NABIL | C6: 40474 | D6: T | E6: SG | F6: 7608 | G6: 40672 | H6: 19414 | I6: PI
A7: DHIBA CONSTRUCTION | B7: NABIL | C7: 40467 | D7: T | E7: SG | F7: 7609 | G7: 40701 | H7: 29414 | I7: PI
A8: DHIBA CONSTRUCTION | B8: NABIL | C8: 40350 | D8: T | E8: SG | F8: 7611 | G8: 40763 | H8: 29414 | I8: PI
A9: DHIBA CONSTRUCTION | B9: NABIL | C9: 40350 | D9: T | E9: SG | F9: 7622 | G9: 40793 | H9: 29414 | I9: PI
A10: DHIBA CONSTRUCTION | B10: NABIL | C10: 40407 | D10: T | E10: SG | F10: 7613 | G10: 40823 | H10: 29414 | I10: PI
A11: DHIBA CONSTRUCTION | B11: NABIL | C11: 40343 | D11: T | E11: SG | F11: 7614 | G11: 40854 | H11: 29414 | I11: PI
A12: DHIBA CONSTRUCTION | B12: NABIL | C12: 40330 | D12: T | E12: SG | F12: 7615 | G12: 40884 | H12: 29418.88 | I12: PI : Dossier remis à M.BOUYA
A13: DHIBA CONSTRUCTION: TOTAL | H13: =SUM(H6:H12) -> 195902.88
A14: ADAROUASSIF OMAR | B14: NABIL | C14: 40357 | D14: T | E14: AWB | F14: 8768 | G14: 40757 | H14: 8986.61 | I14: PI
A15: ADAROUASSIF OMAR | B15: NABIL | C15: 40438 | D15: T | E15: AWB | F15: 8769 | G15: 40788 | H15: 68986.5 | I15: PI
A16: ADAROUASSIF OMAR | B16: NABIL | C16: 40438 | D16: T | E16: AWB | F16: 8771 | G16: 40818 | H16: 68986.6 | I16: PI
A17: ADAROUASSIF OMAR : TANTAN | B17: NABIL | C17: 40309 | D17: T | E17: AWB | F17: 8772 | G17: 40849 | H17: 68986.71 | I17: PI : Dossier remis à M.BOUYA
A18: ADAROUASSIF LAHCEN | B18: NABIL | C18: 40781 | D18: T | E18: BMCE | F18: 9421 | G18: 40933 | H18: 12760.34 | I18: PI
A19: ADAROUASSIF LAHCEN | B19: NABIL | C19: 40781 | D19: T | E19: BMCE | F19: 0292 | G19: 40935 | H19: 25000 | I19: PI
A20: ADAROUASSIF LAHCEN | B20: NABIL | C20: 40781 | D20: T | E20: BMCE | F20: 0293 | G20: 40933 | H20: 250000 | I20: PI
A21: ADAROUASSIF LAHCEN | B21: NABIL | C21: 40781 | D21: T | E21: BMCE | F21: 0291 | G21: 40933 | H21: 25000 | I21: PI
A22: ADAROUASSIF LAHCEN:TANTAN | B22: NABIL | C22: 40781 | D22: T | E22: BMCE | F22: 0295 | G22: 40933 | H22: 33630.5 | I22: PI : Dossier remis à M.BOUYA
A23: ADAROUASSIF LAHCEN: TOTAL | H23: =SUM(H14:H22) -> 562337.26
A24: OUDRA | B24: NABIL | C24: 41243 | D24: C | E24: BP | F24: 7080 | G24: 41250 | H24: 24382.26 | I24: PI : Montant Initial 270 432,26
A25: AHENDOUCH : STE DRAA | B25: NABIL | C25: 41262 | D25: T | E25: CDM | F25: 1680 | G25: 41389 | H25: 49336.63 | I25: PI : Montant Initial 184 273
A26: DAOUDI RACHID | B26: NABIL | C26: 41086 | D26: C | E26: BP | F26: 2143 | G26: 41283 | H26: 73579.33 | I26: PI : Montant Initial 163 134,51
A27: DAOUDI RACHID | B27: NABIL | C27: 41086 | D27: C | E27: BP | F27: 6669 | G27: 41324 | H27: 25000 | I27: PI
A28: DAOUDI RACHID | B28: NABIL | C28: 41086 | D28: C | E28: BP | F28: 6670 | G28: 41330 | H28: 25000 | I28: PI
A29: DAOUDI RACHID | B29: NABIL | C29: 41174 | D29: C | E29: BP | F29: 6671 | G29: 41359 | H29: 25000 | I29: PI
A30: DAOUDI RACHID | B30: NABIL | C30: 41218 | D30: C | E30: BP | F30: 2143 | G30: 41283 | H30: 25886.87 | I30: PI : Montant Initial 163 134,51
A31: DAOUDI RACHID : TOTAL | H31: =SUM(H26:H30) -> 174466.2
A32: AMEJOUD | B32: NABIL | C32: 41048 | D32: C | E32: AWB | F32: 1080 | G32: 41353 | H32: 7818 | I32: PI : Montant Initial 10 818
A33: AMEJOUD | B33: NABIL | C33: 41106 | D33: C | E33: AWB | F33: 1079 | G33: 41384 | H33: 10818 | I33: PI
A34: AMEJOUD | B34: NABIL | C34: 41106 | D34: C | E34: AWB | F34: 1078 | G34: 41414 | H34: 10818 | I34: PI
A35: AMEJOUD | B35: NABIL | C35: 41106 | D35: C | E35: AWB | F35: 1076 | G35: 41445 | H35: 10818 | I35: PI
A36: AMEJOUD | B36: NABIL | C36: 41106 | D36: C | E36: AWB | F36: 1077 | G36: 41475 | H36: 10818 | I36: PI
A37: AMEJOUD | B37: NABIL | C37: 41162 | D37: C | E37: AWB | F37: 1074 | G37: 41506 | H37: 10818 | I37: PI
A38: AMEJOUD | B38: NABIL | C38: 41162 | D38: C | E38: AWB | F38: 1075 | G38: 41537 | H38: 10818 | I38: PI
A39: AMEJOUD | B39: NABIL | C39: 41162 | D39: C | E39: AWB | F39: 1073 | G39: 41598 | H39: 10818 | I39: PI
A40: AMEJOUD | B40: NABIL | C40: 41162 | D40: C | E40: AWB | F40: 1072 | G40: 41598 | H40: 10818 | I40: PI : Dossier remis à M.BOUYA
A41: AMEJOUD : TOTAL | H41: =SUM(H32:H40) -> 94362
A42: LIBARI DOUNYA | B42: NABIL | C42: 41191 | D42: T | F42: 7839 | G42: 41335 | H42: 695.95 | I42: PI : 10 695,95
A43: LIBARI DOUNYA | B43: NABIL | C43: 41052 | D43: T | F43: 5676 | G43: 41341 | H43: 13616.04 | I43: PI : 20 000
...

Sheet OMAR
B2: LISTE DES IMPAYES OMAR AU 31/07/2026
A4: NOM CLIENT | B4: COM | C4: Dte Facture | D4: M | E4: Bqe | F4: N° | G4: Échéance | H4: Montant | I4: Commentaire
A5: BELAADIM HJ LAHCE: MARIKH | B5: OMAR | C5: 41878 | D5: T | E5: BMCE | F5: 373498 | G5: 42144 | H5: 7840 | I5: PI
A6: BELAADIM HJ LAHCEN: ASSMLAL | B6: OMAR | C6: 41818 | D6: T | E6: AWB | F6: 424182 | G6: 42003 | H6: 7000 | I6: PI : REP LE 10/03/15
A7: BELAADIM HJ LAHCEN: ASSMLAL | B7: OMAR | C7: 41818 | D7: T | E7: AWB | F7: 424183 | G7: 42003 | H7: 6780 | I7: PI : REP LE 10/03/15
A8: BELAADIM HJ LAHCEN: ASSMLAL | B8: OMAR | C8: 41878 | D8: T | E8: AWB | F8: 426841 | G8: 42063 | H8: 8500 | I8: PI
A9: BELAADIM HJ LAHCEN:AKARID | B9: OMAR | C9: 42004 | D9: T | E9: AWB | F9: 137306 | G9: 42215 | H9: 8500 | I9: PI
A10: BELAADIM HJ LAHCEN:AROUKAD | B10: OMAR | C10: 41818 | D10: T | E10: CAM | F10: 128385 | G10: 41958 | H10: 37624.64 | I10: PI mnt Initial 147 604,64
A11: BELAADIM HJ LAHCEN:HABYBALLAH | B11: OMAR | C11: 41964 | D11: T | E11: CAM | F11: 151989 | G11: 42217 | H11: 10000 | I11: PI
A12: BELAADIM HJ LAHCEN : TOTAL | H12: =SUM(H5:H11) -> 86244.64
A13: SERIE LMAJD: AFLLA | B13: OMAR | C13: 41626 | D13: T | E13: BMCI | F13: 643839 | G13: 41698 | H13: 171936 | I13: PI
A14: SERIE LMAJD: AFLLA | B14: OMAR | C14: 41626 | D14: T | E14: BMCI | F14: 643840 | G14: 41714 | H14: 169920 | I14: PI
A15: SERIE LMAJD: TOTAL | H15: =SUM(H13:H14) -> 341856
A16: BAKARE | B16: OMAR | C16: 40570 | D16: T | E16: AWB | F16: 1255 | G16: 41615 | H16: 9123.69 | I16: PI mnt Initial 62 123,69-Dossier remis à M.BOUYA
A17: KASSANI | B17: OMAR | C17: 40808 | D17: T | E17: CAM | F17: 415198 | G17: 40923 | H17: 101918.74 | I17: PI -Dossier remis à M.BOUYA
A18: YAHYA OURRAD : MKCH | B18: OMAR | C18: 41425 | D18: C | E18: AWB | F18: 572038 | G18: 41645 | H18: 5191.46 | I18: SIGN NON CONFORME- M Initial 100 000
A19: EL BARI ESSAID | B19: OMAR | C19: 42471 | D19: C | E19: SG | F19: 3126 | G19: 44354 | H19: 25580 | I19: PI MNT INITIAL 90580
A20: EL BARI ESSAID : TOTAL | H20: =SUM(H19:H19) -> 25580
A21: BOUBNINA RADOUANE | B21: OMAR | C21: 42284 | D21: C | E21: AWB | F21: 761083 | G21: 42633 | H21: 67913.54 | I21: PI : MT INITIAL 167 913,54
A22: BOUBNINA RADOUANE | B22: OMAR | C22: 42284 | D22: C | E22: AWB | F22: 761103 | G22: 42741 | H22: 59720 | I22: PI : MT INITIAL 203 110,93
A23: BOUBNINA RADOUANE : TOTAL | H23: =SUM(H21:H22) -> 127633.54
A24: MAHMOUD BOIS | B24: OMAR | C24: 41149 | D24: C | E24: CAM | F24: 103288 | G24: 41628 | H24: 10007.04 | I24: PI mnt Initial38 412,26-Dossier remis à M.BOUYA
A25: ETRANE BOIS+ MAHMOUD BOIS | B25: OMAR | C25: 40967 | D25: C | E25: BP | F25: 370237 | G25: 42663 | H25: 126752.28 | I25: ABSENCE DE COMPTE
A26: ETRANE BOIS+ MAHMOUD BOIS:TOT | H26: =SUM(H24:H25) -> 136759.32
A27: STE EL OILLAF | B27: OMAR | C27: 43189 | D27: T | E27: BP | F27: 747875 | G27: 43536 | H27: 264862.6 | I27: PI
A28: STE EL OILLAF | B28: OMAR | C28: 43189 | D28: T | E28: BP | F28: 747882 | G28: 43578 | H28: 200000 | I28: PI
A29: STE EL OILLAF | B29: OMAR | C29: 43217 | D29: T | E29: BP | F29: 747883 | G29: 43595 | H29: 200000 | I29: PI
A30: STE EL OILLAF | B30: OMAR | C30: 43218 | D30: T | E30: CAM | F30: 600954 | G30: 43641 | H30: 142644.11 | I30: PI
A31: STE EL OILLAF | B31: OMAR | C31: 43251 | D31: T | E31: BP | F31: 747916 | G31: 43564 | H31: 200000 | I31: PI
A32: STE EL OILLAF | B32: OMAR | C32: 43280 | D32: T | E32: BP | F32: 747917 | G32: 43580 | H32: 243602.41 | I32: PI
A33: STE EL OILLAF | B33: OMAR | C33: 43372 | D33: T | E33: CAM | F33: 348986 | G33: 43633 | H33: 100000 | I33: PI
A34: STE EL OILLAF | B34: OMAR | C34: 43157 | D34: T | E34: CAM | F34: 600957 | G34: 43637 | H34: 243526 | I34: PI
A35: STE EL OILLAF | B35: OMAR | C35: 44301 | D35: T | E35: BMCE | F35: 556 | G35: 44439 | H35: 21000 | I35: PI
A36: STE EL OILLAF | B36: OMAR | C36: 44301 | D36: T | E36: BMCE | F36: 557 | G36: 44439 | H36: 20887.56 | I36: PI
A37: STE EL OILLAF : TOTAL | H37: =SUM(H27:H36) -> 1636522.7
A38: IZIKI BOIS | B38: OMAR | C38: 42606 | D38: T | E38: CDM | F38: 7070 | G38: 43854 | H38: 27420.96 | I38: PI : REP LE 18/12/2019
A39: SORETRAD | B39: OMAR | C39: 43666 | D39: C | E39: CAM | F39: 148 | G39: 43915 | H39: 7500 | I39: SUR IMPAYE : PI 4500 MNT INITIAL 35 000DHS
A40: SORETRAD : TOTAL | H40: =SUM(H39:H39) -> 7500
A41: STE WIDAS | B41: OMAR | C41: 44385 | D41: C | E41: BMCE | F41: 7230 | G41: 44385 | H41: 32619.84 | I41: PI : REP LE 20/05/22
A42: STE WIDAS | B42: OMAR | C42: 44433 | D42: C | E42: BMCE | F42: 7275 | G42: 44515 | H42: 10560 | I42: PI : REP LE 20/05/22
...

Sheet DIRECTION
C2: LISTE DES IMPAYES DIRECTION AU 10/07/2026
A5: NOM CLIENT | B5: COM | C5: Dte Facture | D5: M | E5: Bqe | F5: N° | G5: Échéance | H5: Montant | I5: Commentaire
A6: COSCO | B6: DIRCT | C6: 40014 | D6: T | E6: SG | F6: 4086 | G6: 40877 | H6: 52192 | I6: PI: Montant initial 72 192
A7: ESPACE SOFIA | B7: DIRCT | C7: 41545 | D7: T | E7: AWB | F7: 5090 | G7: 41697 | H7: 7516 | I7: PI: Compte 4500
C10: TOTAL IMPAYES DIRECTION | H10: =H6+H7 -> 59708
C13: Total Impayés Direction au 30/01/2025 | H13: 59708 | I13: =($H$10-H13)/H13 -> 0
C14: Total Impayés Direction au 23/01/2025 | H14: 59708 | I14: =($H$10-H14)/H14 -> 0
C15: Total Impayés Direction au | G15: 45673 | H15: 59708 | I15: =($H$10-H15)/H15 -> 0
C19: : Nouvel Impayé
E21: TOTAL IMPAYES DIRECTION
C22: 44987 | E22: 444276
C23: 44994 | E23: 444276
C24: 45001 | E24: 444276
C25: 45008 | E25: 444276
C26: 45015 | E26: 444276
C27: 45022 | E27: 444276
C28: 45029 | E28: 444276
C29: 45036 | E29: 59708
C30: 45043 | E30: 59708
C31: 45051 | E31: 59708
C32: 45057 | E32: 59708
C33: 45064 | E33: 59708
... C110: 45694 | E110: 59708

Sheet FAYCAL
C3: LISTE DES IMPAYES FAYCAL AU 31/07/2026
A6: NOM CLIENT | B6: COM | C6: Dte Facture | D6: M | E6: Bqe | F6: N° | G6: Échéance | H6: Montant | I6: Commentaire
A7: CHERKAOUI ABDESSADEK | B7: Fayçal | C7: 42094 | D7: C | E7: AWB | F7: 8043 | G7: 42686 | H7: 541 | I7: Cheq Prescrit: Montant initial 121 932,02
A8: BOUKRIM EL HOUCINE | B8: Fayçal | C8: 42691 | D8: C | E8: SG | F8: 6978 | G8: 43061 | H8: 62378.92 | I8: PI: Montant initial 70 000
A9: HANDASSA: STROC INDUSTRIE | B9: Fayçal | C9: 42213 | D9: T | E9: BMCE | F9: 6775 | G9: 43221 | H9: 73113.16 | I9: PI
A10: STE KAZETTE :JAMAL DAHIR | B10: Fayçal | C10: 41969 | D10: C | E10: BMCE | F10: 9712 | G10: 43308 | H10: 10000 | I10: CHEQ FRAPE D'INDISPONI:50 000
A11: STE KAZETTE :JAMAL DAHIR | B11: Fayçal | C11: 41969 | D11: C | E11: BMCE | F11: 9718 | G11: 43308 | H11: 50000 | I11: CHEQ FRAPE D'INDISPONIBILITE
A12: STE KAZETTE :JAMAL DAHIR | B12: Fayçal | C12: 41969 | D12: C | E12: BMCE | F12: 9717 | G12: 43308 | H12: 50000 | I12: CHEQ FRAPE D'INDISPONIBILITE
A13: STE KAZETTE :JAMAL DAHIR | B13: Fayçal | C13: 41969 | D13: C | E13: BMCE | F13: 9713 | G13: 43308 | H13: 30000 | I13: CHEQ FRAPE D'INDISPONI:50 000
A14: STE KAZETTE :TOTAL | H14: =SUM(H10:H13) -> 140000
A15: BOUKRIM EL HOUCINE | B15: Fayçal | C15: 42691 | D15: C | E15: SG | F15: 6978 | G15: 43061 | H15: 7621.08 | I15: PI: Montant initial 70 000 Cpte 4500
A16: CHARIKAT AL MISSRI | B16: Fayçal | C16: 43909 | D16: C | E16: BP | F16: 2035 | G16: 43994 | H16: 137179.95 | I16: PI
A17: CHARIKAT AL MISRI LIL AAMAL | B17: Fayçal | C17: 43909 | D17: C | E17: BP | F17: 2029 | G17: 43926 | H17: 39746.26 | I17: PI : REP LE 29/07/20
A18: CHARIKAT AL MISSRI: TOTAL | H18: =SUM(H16:H17) -> 176926.21
A19: JAMALI ESSAID : JAMALI WOOD | B19: Fayçal | C19: 44638 | D19: C | E19: BP | F19: 0011 | G19: 44772 | H19: 700 | I19: PI : MNT INITIAL 51700 REP LE 15/9
A20: JAMALI ESSAID : TOTAL | H20: =SUM(H19:H19) -> 700
A21: ZAROIL YOUSSEF : ALLSTEEL MAROC | B21: Fayçal | C21: 44907 | D21: T | E21: BMCE | F21: 7429 | G21: 44907 | H21: 2353.69 | I21: SIGNATURE NON CONFORME62215,60
A22: ZAROIL YOUSSEF : TOTAL | H22: 2353.69
A23: SOUAF LAHOUCINE : TURKIA SHOP OFFICIEL | B23: Fayçal | C23: 45516 | D23: C | E23: BP | F23: 0037 | G23: 45777 | H23: 7837.69 | I23: PI : MNT INITIAL 10 000
A24: SOUAF LAHOUCINE : TOTAL | H24: =SUM(H23:H23) -> 7837.69
A25: BEDHAJ BOIS: STE IMDOUKAL MERIE | B25: Fayçal | C25: 45925 | D25: T | E25: BMCI | F25: 1659 | G25: 46032 | H25: 56758 | I25: PI MNT INITIAL
A26: BEDHAJ BOIS : TOTAL | H26: =SUM(H25:H25) -> 56758
A27: SBIK : ABOUYOU TRVX DIVERS | B27: Fayçal | C27: 45926 | D27: C | E27: BMCE | F27: 2392 | G27: 45996 | H27: 20000 | I27: PI
A28: SBIK : TOTAL | H28: =SUM(H27:H27) -> 20000
A29: BENNASSER ABDELFATTAH : STE ZAHRAT EL FARAH | B29: Fayçal | C29: 46030 | D29: T | E29: BP | F29: 0101 | G29: 46162 | H29: 138600 | I29: PI REP LE 15/06/2026
A30: BENNASSER ABDELFATTAH : TOTAL | H30: =SUM(H29:H29) -> 138600
A31: BELBARAKA MED SALAH : STE KOUGRI | B31: Fayçal | C31: 45791 | D31: C | E31: AWB | F31: 4424 | G31: 46014 | H31: 5000 | I31: PI REP LE 26/02/2026 MNT INITIAL 25 000
A32: NID YOUSSEF BRAHIM | B32: Fayçal | C32: 45951 | D32: T | E32: SG | F32: 5489 | G32: 46157 | H32: 38000 | I32: PI
A33: STE BANER BOIS | B33: Fayçal | C33: 44797 | D33: T | E33: CDM | F33: 5576 | G33: 46205 | H33: 177069.1 | I33: PI + SIGNATURE NON CONFORME
A34: EL HAMMOUTI BOIS : BOUNAKHLA IBRAHIM YASSIR | B34: Fayçal | C34: 46014 | D34: T | E34: AWB | F34: 4921 | G34: 46203 | H34: 30000 | I34: PI
A35: ANCIEN BOIS | B35: Fayçal | C35: 46118 | D35: C | E35: SAHAM BK | F35: 6186 | G35: 46217 | H35: 29120.03 | I35: SIGNATURE NON CONFORME
A36: G3C | B36: Fayçal | C36: 46062 | D36: T | E36: AWB | F36: 3901 | G36: 46213 | H36: 273888 | I36: PI
A37: GOLD SUD BATIMENT | B37: Fayçal | D37: T | E37: AWB | F37: 0620 | G37: 46227 | H37: 72072 | I37: PI
C42: TOTAL IMPAYES FAYCAL | H42: =H7+H8+H9+H14+H15+H18+H20+H22+H24+H26+H28+H30+H31+H32+H33+H34+H35+H36+H37 -> 1311978.9
C45: Total Impayés FAYCAL au 24/07/2026 | H45: 1239906.9 | I45: =+($H$42-H45)/H45 -> 0.058126946
C46: Total Impayés FAYCAL au 17/07/2026 | H46: 1212911.9 | I46: =+($H$42-H46)/H46 -> 0.081676997
C47: Total Impayés FAYCAL au 10/07/2026 | H47: 1394391.9 | I47: =+($H$42-H47)/H47 -> -0.059103164
C49: : Nouvel Impayé
C52: 45456 | D52: 763053.76
C53: 45463 | D53: 856141.76
...

Sheet NAOUFAL
D2: LISTE DES IMPAYES NAOUFAL AU 31/07/2026
B5: NOM CLIENT | C5: COM | D5: Dte Facture | E5: M | F5: Bqe | G5: N° | H5: Échéance | I5: Montant | J5: Commentaire
B6: ABOUSSALIH HICHAM | C6: NAOUFAL | D6: 44606 | E6: C | F6: AWB | G6: 6084 | H6: 44893 | I6: 134393.12 | J6: PI: MNT INITIAL 167663
B7: ABOUSSALIH HICHAM : TOTAL | I7: =SUM(I6:I6) -> 134393.12
B8: CHAKHMA ABDELKADER | C8: NAOUFAL | D8: 44727 | E8: C | F8: AWB | G8: 3936 | H8: 44855 | I8: 27066.96 | J8: PI
B9: CHAKHMA ABDELKADER | C9: NAOUFAL | D9: 44727 | E9: C | F9: AWB | G9: 3937 | H9: 44862 | I9: 27066.96 | J9: PI
B10: CHAKHMA ABDELKADER | C10: NAOUFAL | D10: 44727 | E10: C | F10: AWB | G10: 3938 | H10: 44872 | I10: 27066.96 | J10: PI
B11: CHAKHMA ABDELKADER | C11: NAOUFAL | D11: 44727 | E11: C | F11: AWB | G11: 3939 | H11: 44876 | I11: 27066.96 | J11: PI
B12: CHAKHMA ABDELKADER | C12: NAOUFAL | D12: 44727 | E12: C | F12: AWB | G12: 3940 | H12: 44883 | I12: 27066.96 | J12: PI
B13: CHAKHMA ABDELKADER | C13: NAOUFAL | D13: 44789 | E13: C | F13: AWB | G13: 7708 | H13: 44890 | I13: 135534.8 | J13: PI
B14: CHAKHMA ABDELKADER : TOTAL | I14: =SUM(I8:I13) -> 270869.6
B15: ELJIBAOUI ABDELHAMID | C15: NAOUFAL | D15: 45012 | E15: C | F15: AWB | G15: 0483 | H15: 45163 | I15: 23624.66 | J15: PI
B16: ELJIBAOUI ABDELHAMID | C16: NAOUFAL | D16: 45189 | E16: C | F16: AWB | G16: 8799 | H16: 45150 | I16: 23000 | J16: PI: REP LE 23/02/24
B17: ELJIBAOUI ABDELHAMID : TOTAL | I17: =SUM(I15:I16) -> 46624.66
B18: STE SORAYASS : STE QUOTIDIEN DESIGN | C18: NAOUFAL | D18: 45568 | E18: T | F18: BP | G18: 0066 | H18: 45736 | I18: 15000 | J18: PI
B19: STE SORAYASS : STE SOS MARRAKECH | C19: NAOUFAL | D19: 45798 | E19: C | F19: CAM | G19: 9291 | H19: 45838 | I19: 50734 | J19: PI REP LE 13/08/25 MNT INITIAL 57 000
B20: STE SORAYASS : STE MARGHOUME SAKAN | C20: NAOUFAL | D20: 45713 | E20: C | F20: AWB | G20: 8692 | H20: 45828 | I20: 100000 | J20: PI
B21: STE SORAYASS : KAMAL DARAI | C21: NAOUFAL | D21: 45897 | E21: C | F21: AWB | G21: 0611 | H21: 46010 | I21: 35000 | J21: PI
B22: STE SORAYASS : KAMAL DARAI | C22: NAOUFAL | D22: 45897 | E22: C | F22: AWB | G22: 0610 | H22: 46017 | I22: 35000 | J22: PI
B23: STE SORAYASS : KAMAL DARAI | C23: NAOUFAL | D23: 45897 | E23: C | F23: AWB | G23: 0612 | H23: 46022 | I23: 35000 | J23: PI
B24: STE SORAYASS : KAMAL DARAI | C24: NAOUFAL | D24: 45897 | E24: C | F24: AWB | G24: 0609 | H24: 46031 | I24: 35000 | J24: PI
B25: STE SORAYASS | C25: NAOUFAL | D25: 45896 | E25: C | F25: BMCE | G25: 6155 | H25: 46048 | I25: 11423 | J25: PI : MNT INITIAL 56 250
B26: STE SORAYASS | C26: NAOUFAL | D26: 45896 | E26: C | F26: BMCE | G26: 6156 | H26: 46050 | I26: 56514.51 | J26: PI
B27: STE SORAYASS | C27: NAOUFAL | D27: 45896 | E27: T | F27: BMCE | G27: 7179 | H27: 46121 | I27: 56900 | J27: PI
B28: STE SORAYASS | C28: NAOUFAL | D28: 45933 | E28: T | F28: BMCE | G28: 7180 | H28: 46122 | I28: 56702.15 | J28: PI
B29: STE SORAYASS | C29: NAOUFAL | D29: 45933 | E29: T | F29: BMCE | G29: 7182 | H29: 46127 | I29: 48500 | J29: PI
... B33: STE SORAYASS | C33: NAOUFAL | D33: 45968 | E33: T | F33: BMCE | G33: 7268 | H33: 46150 | I33: 43000 | J33: PI
B34: STE SORAYASS | C34: NAOUFAL | D34: 45980 | E34: T | F34: BMCE | G34: 7271 | H34: 46155 | I34: 42100
B35: STE SORAYASS | C35: NAOUFAL | D35: 45980 | E35: T | F35: BMCE | G35: 7273 | H35: 46157 | I35: 41900 | J35: PI
B36: STE SORAYASS | C36: NAOUFAL | D36: 45980 | E36: T | F36: BMCE | G36: 7274 | H36: 46160 | I36: 41800 | J36: PI
B37: STE SORAYASS | C37: NAOUFAL | D37: 45980 | E37: T | F37: BMCE | G37: 7275 | H37: 46161 | I37: 42150 | J37: PI
B38: STE SORAYASS | C38: NAOUFAL | D38: 45980 | E38: T | F38: BMCE | G38: 7276 | H38: 46162 | I38: 42200 | J38: PI
B39: STE SORAYASS | C39: NAOUFAL | D39: 45996 | E39: T | F39: BMCE | G39: 7993 | H39: 46185 | I39: 37100 | J39: PI
B40: STE SORAYASS | C40: NAOUFAL | D40: 45996 | E40: T | F40: BMCE | G40: 7994 | H40: 46188 | I40: 37200 | J40: PI
B41: STE SORAYASS | C41: NAOUFAL | D41: 45996 | E41: T | F41: BMCE | G41: 7996 | H41: 46192 | I41: 37400 | J41: PI
B42: STE SORAYASS | C42: NAOUFAL | D42: 46062 | E42: T | F42: BMCE | G42: 7998 | H42: 46197 | I42: 39700 | J42: PI
B43: STE SORAYASS | C43: NAOUFAL | D43: 45996 | E43: T | F43: BMCE | G43: 7997 | H43: 46195 | I43: 37704.78 | J43: PI
B44: STE SORAYASS | C44: NAOUFAL | D44: 46062 | E44: T | F44: BMCE | G44: 8000 | H44: 46199 | I44: 39900 | J44: PI
B45: STE SORAYASS | C45: NAOUFAL | D45: 46062 | E45: T | F45: BMCE | G45: 8001 | H45: 46203 | I45: 39975.39 | J45: PI
B46: STE SORAYASS | C46: NAOUFAL | D46: 46062 | E46: T | F46: BMCE | G46: 8003 | H46: 46205 | I46: 40100 | J46: PI
...

Sheet FAHD
D3: LISTE DES IMPAYES FAHD AU 31/07/2026
B6: NOM CLIENT | C6: COM | D6: Dte Facture | E6: M | F6: Bqe | G6: N° | H6: Échéance | I6: Montant | J6: Commentaire
B7: AIT HAMOU ABDELLATIF : AIT HAMMOU MED | C7: FAHD | D7: 44616 | E7: C | F7: CDM | G7: 3126 | H7: 44635 | I7: 35000 | J7: PI
B8: HAJAR BOIS : REBEL CONSTRUCTION | C8: FAHD | D8: 45735 | E8: T | F8: BMCE | G8: 7936 | H8: 45828 | I8: 16812.5 | J8: PI MNT INITIAL 33 625
B9: HAJAR BOIS : MY BELLA BATIMENT | C9: FAHD | D9: 45735 | E9: T | F9: BMCE | G9: 4939 | H9: 45868 | I9: 48 | J9: PI MNT INITIAL 16 000
B10: HAJAR BOIS | C10: FAHD | D10: 45796 | E10: T | F10: AWB | G10: 5528 | H10: 46016 | I10: 95000 | J10: PI
B11: HAJAR BOIS | C11: FAHD | D11: 45786 | E11: T | F11: AWB | G11: 5527 | H11: 46011 | I11: 85000 | J11: PI
B12: HAJAR BOIS | C12: FAHD | D12: 45833 | E12: T | F12: AWB | G12: 5543 | H12: 46022 | I12: 80419.2 | J12: PI
B13: HAJAR BOIS | C13: FAHD | D13: 45833 | E13: T | F13: AWB | G13: 5544 | H13: 46032 | I13: 90000 | J13: PI
B14: HAJAR BOIS : MED ABJAOU | C14: FAHD | D14: 45911 | E14: T | F14: BMCE | G14: 9474 | H14: 46111 | I14: 7600 | J14: PI
B15: HAJAR BOIS : MED ABJAOU | C15: FAHD | D15: 45911 | E15: T | F15: BMCE | G15: 2414 | H15: 46111 | I15: 20000 | J15: PI
B16: HAJAR BOIS : LINA WOOD | C16: FAHD | D16: 45944 | E16: T | F16: BP | G16: 0038 | H16: 46122 | I16: 123617.62 | J16: PI
B17: HAJAR BOIS : MED ABJAOU | C17: FAHD | D17: 45959 | E17: T | F17: BMCE | G17: 9479 | H17: 46142 | I17: 10000 | J17: PI
B18: HAJAR BOIS : MED ABJAOU | C18: FAHD | D18: 45841 | E18: T | F18: BMCE | G18: 2411 | H18: 46142 | I18: 15000 | J18: PI
... B22: HAJAR BOIS : LINA WOOD | C22: FAHD | D22: 45959 | E22: T | F22: BP | G22: 0028 | H22: 46063 | I22: 105728.81 | J22: PI REP LE 15/05/26
B23: HAJAR BOIS : MED ABJAOU | C23: FAHD | D23: 45845 | E23: T | F23: BMCE | G23: 2438 | H23: 46172 | I23: 35000
B24: HAJAR BOIS : MED ABJAOU | C24: FAHD | D24: 45989 | E24: T | F24: BMCE | G24: 2442 | H24: 46172 | I24: 20000
B25: HAJAR BOIS : TOTAL | I25: =SUM(I8:I24) -> 902985.64
B26: BADOUR GHA SERVICE | C26: FAHD | D26: 45104 | E26: C | F26: CIH | G26: 6833 | H26: 45131 | I26: 2089.92 | J26: PI REP LE 04/03/24
B27: AL AIN AMEUBLEMENT | C27: FAHD | D27: 45519 | E27: T | F27: CDM | G27: 7636 | H27: 45642 | I27: 4949.78 | J27: PI: MNT INITIAL 40 000
B28: AL AIN AMEUBLEMENT | C28: FAHD | D28: 45523 | E28: T | F28: CDM | G28: 7635 | H28: 45656 | I28: 32813.73 | J28: PI
B29: AL AIN AMEUBLEMENT : TOTAL | I29: =SUM(I27:I28) -> 37763.51
B30: KAFIF LARBI | C30: FAHD | D30: 45259 | E30: C | F30: BMCE | G30: 1027 | H30: 45290 | I30: 15280 | J30: PI : REP LE 29/11/24-16/12/24 : 55 280
B31: STE AGA FERME | C31: FAHD | D31: 45980 | E31: T | F31: SG | G31: 4563 | H31: 46069 | I31: 24687.55 | J31: PI
B32: STE AGA FERME | C32: FAHD | D32: 45980 | E32: T | F32: SG | G32: 4560 | H32: 46076 | I32: 24685 | J32: PI
B33: STE AGA FERME | C33: FAHD | D33: 46017 | E33: T | F33: SG | G33: 4648 | H33: 46167 | I33: 18023 | J33: PI
B34: STE AGA FERME | C34: FAHD | D34: 46031 | E34: T | F34: SG | G34: 4647 | H34: 46182 | I34: 18023 | J34: PI
B35: STE AGA FERME | C35: FAHD | D35: 46031 | E35: T | F35: SG | G35: 4644 | H35: 46189 | I35: 18023 | J35: PI
B36: STE AGA FERME | C36: FAHD | D36: 46031 | E36: T | F36: SG | G36: 4643 | H36: 46192 | I36: 18023 | J36: PI
B37: STE AGA FERME | C37: FAHD | D37: 46055 | E37: T | F37: SG | G37: 4639 | H37: 46196 | I37: 18023 | J37: PI
B38: STE AGA FERME | C38: FAHD | D38: 46071 | E38: T | F38: SG | G38: 4638 | H38: 46199 | I38: 18023 | J38: PI
B39: STE AGA FERME | C39: FAHD | D39: 46095 | E39: T | F39: SG | G39: 4635 | H39: 46210 | I39: 18028.36 | J39: PI
B40: STE AGA FERME : TOTAL | I40: =SUM(I31:I39) -> 175538.91
B41: FREMBAL | C41: FAHD | D41: 45628 | E41: C | F41: AWB | G41: 4059 | H41: 45880 | I41: 20000 | J41: PI : REP LE 09/01/26
B42: FREMBAL | C42: FAHD | D42: 45923 | E42: C | F42: AWB | G42: 5525 | H42: 46112 | I42: 36115.4 | J42: PI
B43: FREMBAL : TOTAL | I43: =SUM(I41:I42) -> 56115.4
B44: STE ELUXE BTP | C44: FAHD | D44: 45852 | E44: C | F44: CAM | G44: 4299 | H44: 46056 | I44: 106757.73 | J44: PI
B45: STE ELUXE BTP | C45: FAHD | D45: 45913 | E45: C | F45: CAM | G45: 4290 | H45: 46064 | I45: 185563.8
B46: STE ELUXE BTP : TOTAL | I46: =SUM(I44:I45) -> 292321.53
B47: STE LINA WOOD | C47: FAHD | D47: 45933 | E47: T | F47: BP | G47: 0046 | H47: 46101 | I47: 114061.24 | J47: PI
...

Sheet GII
C3: LISTE DES IMPAYES GII AU 31/07/26
A6: NOM CLIENT | B6: COM | C6: Dte Facture | D6: M | E6: Bqe | F6: N° | G6: Échéance | H6: Montant | I6: Commentaire
A7: MERIE ADEBO : DABACH | B7: GII | C7: 40565 | D7: C | E7: AWB | F7: 2134 | G7: 40846 | H7: 11634.84 | I7: PI: Montant initial 67 176
A8: EL BIAD KHALID | B8: GII | C8: 40231 | D8: T | E8: BMCE | F8: 2733 | G8: 40877 | H8: 500 | I8: PI: Montant initial 4 135,14 : M.BOUYA
A9: STE FASK BOIS | B9: GII | C9: 40929 | D9: T | E9: BP | F9: 5371 | G9: 41039 | H9: 49028.08 | I9: PI MNT INITIAL 156 200
A10: STE FASK BOIS | B10: GII | C10: 40929 | D10: T | E10: BP | F10: 5369 | G10: 41151 | H10: 156054.83 | I10: PI
A11: STE FASK BOIS | B11: GII | C11: 40971 | D11: T | E11: BP | F11: 5373 | G11: 41162 | H11: 81000 | I11: PI
A12: STE FASK BOIS | B12: GII | C12: 40971 | D12: T | E12: BP | F12: 5374 | G12: 41172 | H12: 81100 | I12: PI
A13: STE FASK BOIS | B13: GII | C13: 40981 | D13: T | E13: BP | F13: 5375 | G13: 41182 | H13: 81050 | I13: PI
A14: STE FASK BOIS | B14: GII | C14: 40981 | D14: T | E14: BP | F14: 5376 | G14: 41192 | H14: 81200 | I14: PI
A15: STE FASK BOIS | B15: GII | C15: 41017 | D15: T | E15: BP | F15: 5377 | G15: 41202 | H15: 81400 | I15: PI
A16: STE FASK BOIS | B16: GII | C16: 41017 | D16: T | E16: BP | F16: 5378 | G16: 41213 | H16: 81300 | I16: PI
A17: STE FASK BOIS | B17: GII | C17: 41017 | D17: T | E17: BP | F17: 5380 | G17: 41223 | H17: 81500 | I17: PI
A18: STE FASK BOIS | B18: GII | C18: 41036 | D18: T | E18: BP | F18: 5382 | G18: 41233 | H18: 81060 | I18: PI
A19: STE FASK BOIS | B19: GII | C19: 41083 | D19: T | E19: BP | F19: 5381 | G19: 41243 | H19: 79712.79 | I19: PI
A20: STE FASK BOIS | B20: GII | C20: 41129 | D20: T | E20: BP | F20: 7771 | G20: 41375 | H20: 165543.13 | I20: PI : remis à la bq le 20/01/14
A21: STE FASK BOIS | B21: GII | C21: 41201 | D21: T | E21: BP | F21: 7772 | G21: 41379 | H21: 234058.03 | I21: PI : remis à la bq le 20/01/14
A22: STE FASK BOIS : TOTAL | H22: =SUM(H9:H21) -> 1334006.9
A23: EVA CUISINE | B23: GII | C23: 43158 | D23: T | E23: BP | F23: 9864 | G23: 43342 | H23: 5000 | I23: PI: Versé le 08/05/19
A24: EVA CUISINE | B24: GII | C24: 43167 | D24: T | E24: BP | F24: 9866 | G24: 43373 | H24: 5000 | I24: PI: Versé le 08/05/19
A25: EVA CUISINE | B25: GII | C25: 43167 | D25: T | E25: BP | F25: 9865 | G25: 43358 | H25: 5000 | I25: PI: Versé le 08/05/19
A26: EVA CUISINE : TOTAL | H26: =SUM(H23:H25) -> 15000
A27: MERIE ABOUELAOULA:BENHLAL SMAIL | B27: GII | C27: 43820 | D27: C | E27: CDM | F27: 6477 | G27: 44502 | H27: 26348.89 | I27: PI : Montant cheque versé 135 802,04
A28: STE DECOMARK | B28: GII | C28: 43227 | D28: C | E28: BMCE | F28: 1844 | G28: 43845 | H28: 813.7 | I28: PI
A29: MOBASSM TRAVAUX | B29: GII | C29: 43484 | D29: T | E29: CAM | F29: 2681 | G29: 43905 | H29: 4567.99 | I29: PI: Montant initial 8 567,99
A30: TARGA BOIS | B30: GII | C30: 43383 | D30: T | E30: CAM | F30: 4958 | G30: 44134 | H30: 10000 | I30: PI
A31: TARGA BOIS | B31: GII | C31: 43383 | D31: T | E31: CAM | F31: 4960 | G31: 44104 | H31: 5570 | I31: PI : REP LE 09/11/20
A32: TARGA BOIS | B32: GII | C32: 43383 | D32: T | E32: CAM | F32: 4959 | G32: 44165 | H32: 10000 | I32: PI
A33: TARGA BOIS : TOTAL | H33: =SUM(H30:H32) -> 25570
A34: LACHGAR ABDERRAZAK | B34: GII | C34: 44721 | D34: C | E34: AWB | F34: 4558 | G34: 44726 | H34: 2277 | I34: PI : REP LE 04/07/22 MNT INITIAL 2777
A35: STE NOUVELLE CONSTRADINE | B35: GII | C35: 44471 | D35: T | E35: BP | F35: 3831 | G35: 44767 | H35: 14461.5 | I35: PI : MNT INITIAL 143406
A36: DIGINET COMPUTER : BADR HANGA | B36: GII | C36: 44526 | D36: T | E36: AWB | F36: 2485 | G36: 45519 | H36: 2567.54 | I36: PI MNT INITIAL 3000
A37: DIGINET COMPUTER : BADR HANGA | B37: GII | C37: 44526 | D37: T | E37: AWB | F37: 2486 | G37: 45550 | H37: 3000 | I37: PI
A38: DIGINET COMPUTER : BADR HANGA | B38: GII | C38: 44526 | D38: T | E38: AWB | F38: 2487 | G38: 45580 | H38: 3000 | I38: PI
A39: DIGINET COMPUTER : TOTAL | H39: =SUM(H36:H38) -> 8567.54
A40: STE AOUTA LUM | B40: GII | C40: 44921 | D40: C | E40: CDM | F40: 1567 | G40: 44942 | H40: 1700 | I40: PI : VAC
A41: MUSTAPHA MOUDNIB | B41: GII | C41: 44812 | D41: C | E41: BMCE | F41: 1535 | G41: 44985 | H41: 14120 | I41: PI MNT INITIAL 64 120
A42: STE IDEA HOUSE | B42: GII | C42: 45071 | D42: T | E42: AWB | F42: 1485 | G42: 45117 | H42: 969 | I42: PI MNT INITIAL 7169
A43: AMCHAHRO ABDELLAH | B43: GII | C43: 45164 | D43: C | E43: AWB | F43: 8890 | G43: 45376 | H43: 5000 | I43: PI MNT INITIAL 7000
A44: AMCHAHRO ABDELLAH | B44: GII | C44: 45209 | D44: C | E44: AWB | F44: 8891 | G44: 45407 | H44: 7000 | I44: PI
...

Sheet LAHCEN
D3: LISTE DES IMPAYES LAHCEN AU 31/07/2026
B6: NOM CLIENT | C6: COM | D6: Dte Facture | E6: M | F6: Bqe | G6: N° | H6: Échéance | I6: Montant | J6: Commentaire
B7: STE ZEGHDANI MULTISCES | C7: LAHCEN | D7: 45975 | E7: T | F7: AWB | G7: 7056 | H7: 46111 | I7: 99737.3 | J7: PI MNT INITIAL 102 795,30
B8: STE ZEGHDANI MULTISCES : TOTAL | I8: =SUM(I7:I7) -> 99737.3
B9: ALTIT BOIS : RISSIELKA ALUMINIUM | C9: LAHCEN | D9: 46249 | E9: T | F9: AWB | G9: 6962 | H9: 46076 | I9: 5000 | J9: PI
B10: ALTIT BOIS : TOTAL | I10: =SUM(I9:I9) -> 5000
B11: BELAADIM AHMED SIDI BIBO : RACHID IHIHI | C11: LAHCEN | D11: 45866 | E11: C | F11: AWB | G11: 1834 | H11: 46112 | I11: 17900 | J11: PI
B12: BELAADIM AHMED SIDI BIBO : RACHID IHIHI | C12: LAHCEN | D12: 45866 | E12: C | F12: AWB | G12: 1833 | H12: 46142 | I12: 17800 | J12: PI
B13: BELAADIM AHMED SIDI BIBO : RACHID IHIHI | C13: LAHCEN | D13: 45866 | E13: C | F13: AWB | G13: 1835 | H13: 46174 | I13: 17800 | J13: PI
B14: BELAADIM AHMED SIDI BIBO : TOTAL | I14: =SUM(I11:I13) -> 53500
D16: TOTAL IMPAYES LAHCEN | I16: =I8+I10+I14 -> 158237.3
D19: TOTAL IMPAYES LAHCEN AU 24/07/2026 | I19: 158237.3 | J19: =+($I$16-I19)/I19 -> 0
D20: TOTAL IMPAYES LAHCEN AU 17/07/2026 | I20: 158237.3 | J20: =+($I$16-I20)/I20 -> 0
D21: TOTAL IMPAYES LAHCEN AU 10/07/2026 | I21: 247037.3 | J21: =+($I$16-I21)/I21 -> -0.35945989
C25: : Nouvel Impayé
C27: 45827 | D27: 128900
C28: 45842 | D28: 138780
C29: 45848 | D29: 197753
C30: 45856 | D30: 352988.52
C31: 45863 | D31: 437988.52
C32: 45880 | D32: 520602.79
C33: 45891 | D33: 520602.79
C34: 45919 | D34: 592007.79
C35: 45925 | D35: 512325.27
C36: 45933 | D36: 448772.27
C37: 45940 | D37: 394772.27
C38: 45947 | D38: 334085.27
... C69: 46234 | D69: 158237.3

Sheet RACHID
D3: LISTE DES IMPAYES RACHID AU 31/07/2026
B6: NOM CLIENT | C6: COM | D6: Dte Facture | E6: M | F6: Bqe | G6: N° | H6: Échéance | I6: Montant | J6: Commentaire
B7: NACIRI MED : STE WOOD RAIS SCE | C7: RACHID | D7: 45712 | E7: T | F7: CAM | G7: 4180 | H7: 45755 | I7: 6500 | J7: PI
B8: NACIRI MED : STE PRO TRAV CONSTR | C8: RACHID | D8: 45776 | E8: T | F8: AWB | G8: 1041 | H8: 45848 | I8: 5000 | J8: SIGNATURE NON CONFORME
B9: NACIRI MED : TOTAL | I9: =SUM(I7:I8) -> 11500
B10: JUMATIK IMMOBILIER | C10: RACHID | D10: 45254 | E10: C | F10: AWB | G10: 5644 | H10: 45337 | I10: 141288 | J10: PI
B11: JUMATIK IMMOBILIER | C11: RACHID | D11: 45245 | E11: C | F11: AWB | G11: 5629 | H11: 45332 | I11: 136416 | J11: PI
B12: JUMATIK IMMOBILIER | C12: RACHID | D12: 45258 | E12: C | F12: AWB | G12: 5675 | H12: 45355 | I12: 93528 | J12: PI
B13: JUMATIK IMMOBILIER : TOTAL | I13: =SUM(I10:I12) -> 371232
B14: JS BOIS | C14: RACHID | D14: 45306 | E14: C | F14: AWB | G14: 5800 | H14: 45391 | I14: 30000 | J14: PI
B15: JS BOIS | C15: RACHID | D15: 45306 | E15: C | F15: AWB | G15: 5798 | H15: 45393 | I15: 30000 | J15: PI
B16: JS BOIS | C16: RACHID | D16: 45306 | E16: C | F16: AWB | G16: 5797 | H16: 45398 | I16: 30000 | J16: PI
B17: JS BOIS | C17: RACHID | D17: 45337 | E17: C | F17: AWB | G17: 9832 | H17: 45420 | I17: 50000 | J17: PI
B18: JS BOIS | C18: RACHID | D18: 45371 | E18: C | F18: AWB | G18: 9834 | H18: 45427 | I18: 50000 | J18: PI
B19: JS BOIS | C19: RACHID | D19: 45377 | E19: C | F19: AWB | G19: 9831 | H19: 45434 | I19: 50000 | J19: PI
B20: JS BOIS | C20: RACHID | D20: 45325 | E20: C | F20: AWB | G20: 9833 | H20: 45434 | I20: 50000 | J20: PI
B21: JS BOIS | C21: RACHID | D21: 45309 | E21: C | F21: AWB | G21: 9813 | H21: 45434 | I21: 140000 | J21: PI
B22: JS BOIS | C22: RACHID | D22: 45325 | E22: C | F22: AWB | G22: 9835 | H22: 45434 | I22: 67277.39 | J22: PI
B23: JS BOIS : TOTAL | I23: =SUM(I14:I22) -> 497277.39
B24: ZEKNOUN RACHID : LAABIDI | C24: RACHID | D24: AVANCE | E24: C | F24: BP | G24: 0067 | H24: 46068 | I24: 24500 | J24: PI MNT INITIAL 43 000
B25: ZEKNOUN RACHID : GUESSMI BRAHIM | C25: RACHID | D25: 45945 | E25: T | F25: AWB | G25: 9549 | H25: 46101 | I25: 20700 | J25: PI
B26: ZEKNOUN RACHID : IKHLAS DECOR | C26: RACHID | D26: 45972 | E26: C | F26: SAHAM BK | G26: 4953 | H26: 46122 | I26: 21089 | J26: PI
B27: ZEKNOUN RACHID : TOTAL | I27: =SUM(I24:I26) -> 66289
B28: ABOU BAKR KHABA : MAQAM CONCEPT | C28: RACHID | D28: 45539 | E28: C | F28: AWB | G28: 2437 | H28: 45656 | I28: 25000 | J28: PI
B29: ABOU BAKR KHABBA : MOATAZ BOIS | C29: RACHID | D29: 45664 | E29: C | F29: AWB | G29: 2261 | H29: 45723 | I29: 8200 | J29: PI REP LE 10/07/25
B30: ABOU BAKR KHABA : TOTAL | I30: =SUM(I28:I29) -> 33200
B31: BURMOS : STE SEUQE TRAV | C31: RACHID | D31: 45888 | E31: C | F31: CAM | G31: 5516 | H31: 45989 | I31: 40700 | J31: PI REP LE 09/12/25
B32: TABI BOIS: WAHAB CHAIMAA | C32: RACHID | D32: 45623 | E32: C | F32: AWB | G32: 4945 | H32: 46041 | I32: 40000
B33: TABI BOIS: WAHAB CHAIMAA | C33: RACHID | D33: 45623 | E33: C | F33: AWB | G33: 4946 | H33: 46041 | I33: 40000
B34: TABI BOIS: WAHAB CHAIMAA | C34: RACHID | D34: 45623 | E34: C | F34: AWB | G34: 4947 | H34: 46041 | I34: 40000
B35: TABI BOIS: WAHAB CHAIMAA | C35: RACHID | D35: 45623 | E35: C | F35: AWB | G35: 4948 | H35: 46041 | I35: 40000
B36: TABI BOIS: WAHAB CHAIMAA | C36: RACHID | D36: 45623 | E36: C | F36: AWB | G36: 4949 | H36: 46041 | I36: 40000
B37: TABI BOIS: TOTAL | I37: =SUM(I32:I36) -> 200000
B38: BOUGDOUR WOOD : BOUGDOUR TIMBRE | C38: RACHID | D38: 45952 | E38: C | F38: AWB | G38: 7206 | H38: 46063 | I38: 11664 | J38: PI REP LE 30/04/26 MNT INITIAL 76 664
B39: BOUGDOUR WOOD | C39: RACHID | D39: 45903 | E39: T | F39: AWB | G39: 3047 | H39: 46154 | I39: 35000 | J39: PI
B40: BOUGDOUR WOOD | C40: RACHID | D40: 45903 | E40: T | F40: AWB | G40: 3048 | H40: 46161 | I40: 36000 | J40: PI
B41: BOUGDOUR WOOD | C41: RACHID | D41: 45903 | E41: T | F41: AWB | G41: 3049 | H41: 46182 | I41: 36000 | J41: PI
B42: BOUGDOUR WOOD | C42: RACHID | D42: 45903 | E42: T | F42: AWB | G42: 3050 | H42: 46189 | I42: 36500 | J42: PI
B43: BOUGDOUR WOOD | C43: RACHID | D43: 45903 | E43: T | F43: AWB | G43: 3052 | H43: 46203 | I43: 37000 | J43: PI
B44: BOUGDOUR WOOD | C44: RACHID | D44: 45903 | E44: T | F44: AWB | G44: 3053 | H44: 46210 | I44: 37000 | J44: PI
...

Sheet OUSSAMA
D3: LISTE DES IMPAYES OUSSAMA AU 31/07/2026
B6: NOM CLIENT | C6: COM | D6: Dte Facture | E6: M | F6: Bqe | G6: N° | H6: Échéance | I6: Montant | J6: Commentaire
B7: LARIBAT CONSTRUCTION | C7: OUSSAMA | D7: 46137 | E7: C | F7: SAHAM BK | G7: 6755 | H7: 46201 | I7: 12474 | J7: MANQUE DEUXIEME SIGNATURE
D12: TOTAL IMPAYES OUSSAMA | I12: =+I7 -> 12474
D15: TOTAL IMPAYES OUSSAMA AU 24/07/2026 | I15: 12474 | J15: =($I$12-I15)/I15 -> 0
D16: TOTAL IMPAYES OUSSAMA AU 17 /07 /2026 | I16: 12474 | J16: =($I$12-I16)/I16 -> 0
D17: TOTAL IMPAYES OUSSAMA AU 10/07/2026 | I17: 35541.03 | J17: =($I$12-I17)/I17 -> -0.64902537
D21: TOTAL IMPAYES OUSSAMA
C23: 45827 | D23: 0
C24: 45842 | D24: 0
C25: 45848 | D25: 25000
C26: 45856 | D26: 25000
C27: 45863 | D27: 25000
C28: 45880 | D28: 22700
C29: 45891 | D29: 22700
C30: 45919 | D30: 0
C31: 45925 | D31: 0
C32: 45968 | D32: 0
C33: 45975 | D33: 87000
C34: 45982 | D34: 0
... C49: 46234 | D49: 12474
